Workbook

Sheet ACTIF
A1: Actif | B1: Exercice 2025
B2: TAFADIS
A3: Libellé | B3: Brut | C3: Amorti. / Provo. | D3: Net 2025
A4: ACTIFS NON COURANTS
A5: Ecart d’acquisition (ou goodwill)
A6: Immobilisations incorporelles | B6: 790800 | C6: 566800 | D6: =B6-C6 -> 224000
A7: Immobilisations corporelles | B7: =SUM(B8:B11) -> 81711786 | C7: =SUM(C8:C11) -> 39512791 | D7: =SUM(D8:D11) -> 42198995
A8: Terrains
A9: Bâtiments | B9: 0 | C9: 0
A10: Autres immobilisations Corporelles | B10: 81711786 | C10: 39512791 | D10: =B10-C10 -> 42198995
A11: Immobilisations en concession | C11: 0
A12: Immobilisations en cours
A13: Immobilisations financières | B13: =SUM(B14:B17) -> 1326600 | C13: =SUM(C14:C17) -> 0 | D13: =SUM(D14:D17) -> 1326600
A14: Titres mis en équivalence | B14: 0 | C14: 0 | D14: =B14-C14 -> 0
A15: Autres participations et créances rattachées | B15: 0 | C15: 0 | D15: =B15-C15 -> 0
A16: Autres titres immobilisés | B16: 0 | C16: 0 | D16: =B16-C16 -> 0
A17: Prêts et autres actifs financiers non courants | B17: 1326600 | C17: 0 | D17: =B17-C17 -> 1326600
A18: Impôts différés actif | B18: 5900437 | D18: =B18-C18 -> 5900437
A19: TOTAL ACTIF NON COURANT | B19: =B6+B7+B12+B13+B18 -> 89729623 | C19: =C5+C6+C7+C12+C13+C18 -> 40079591 | D19: =D6+D7+D12+D13+D18 -> 49650032
A20: ACTIF COURANT
A21: Stocks et encours | B21: 2873630 | C21: 0 | D21: =B21-C21 -> 2873630
A22: Créances et emplois assimilés | B22: =B23+B24+B25+B26 -> 229217850 | C22: =C23+C24+C25+C26 -> 91095376 | D22: =D23+D24+D25+D26 -> 138122474
A23: Clients | B23: 206504270 | C23: 91095376 | D23: =B23-C23 -> 115408894
A24: Autres débiteurs | B24: 3582159 | C24: 0 | D24: =B24-C24 -> 3582159
A25: Impôts et assimilés | B25: 19131421 | C25: 0 | D25: =B25-C25 -> 19131421
A26: Autres créances et emplois Assimilés | B26: 0 | C26: 0 | D26: =B26-C26 -> 0
A27: Disponibilités et assimilés | B27: =B29+B28 -> 59095935 | C27: =C29+C28 -> 0 | D27: =B27-C27 -> 59095935
A28: Placements et autres actifs financiers courants
A29: Trésorerie | B29: 59095935 | C29: 0 | D29: =B29-C29 -> 59095935
A30: TOTAL ACTIF COURANT | B30: 291187417 | C30: =C21+C22+C27 -> 91095376 | D30: =B30-C30 -> 200092041
A31: TOTAL GENERAL ACTIF | B31: 380917042 | C31: =C19+C30 -> 131174967 | D31: =D19+D30 -> 249742073

Sheet PASSIF
A1: EXERCICE 2025
B2: TAFADIS
A3: Libellé | B3: Exercice 2025
A4: CAPITAUX PROPRES
A5: Capital émis | B5: 24600000
A6: Capital non appelé
A7: Autres dotations en fonds propres
A8: Primes et réserves / (Réserves consolidées(1)) | B8: 27719907
A9: Ecart de réévaluation
A10: Ecart d’équivalence (1)
A11: Résultat net / (Résultat net part du groupe (1)) | B11: =TR!B34 -> 22780769
A12: Autres capitaux propres - Report à nouveau | B12: 74826989
A13: Compte de Liaison
A14: Part de la société consolidant (1)
A15: Part des minoritaires (1)
A16: TOTAL CAPITAUX PROPRES I | B16: =SUM(B5:B15) -> 149927665
A17: PASSIFS NON-COURANTS
A18: Emprunts et dettes financières | B18: 0
A19: Impôts (différés et provisionnés) | B19: 0
A20: Autres dettes non courantes | B20: 0
A21: Provisions et produits constatés d’avance | B21: 4085732
A22: TOTAL PASSIFS NON COURANTS II | B22: =SUM(B18:B21) -> 4085732
A23: PASSIFS COURANTS
A24: Fournisseurs et comptes rattachés | B24: 8741154
A25: Impôts | B25: 50109882
A26: Autres dettes | B26: 36877639
A27: Trésorerie passif
A28: TOTAL PASSIFS COURANTS III | B28: =B24+B25+B26+B27 -> 95728675
A29: TOTAL GENERAL PASSIF ( I+II+III) | B29: =B16+B22+B28 -> 249742072
A30: perte de valeur sur les actions
B33: =B29-Bilan_financier!C38 -> -131174968

Sheet Journal_retraitement
B3: Journal de retraitements
B6: Comptes | D6: Libéllés | I6: Montants
B7: Débit | C7: Crédit | I7: Débit | J7: Crédit
B8: 28 | D8: Retraitement dotations aux amortissements IMMO INCOR | I8: =ACTIF!C6 -> 566800
C9: 116 | D9: Retraitement dotations aux amortissements IMMO INCOR | J9: =ACTIF!C6 -> 566800
B10: 28 | D10: Retraitement dotations aux amortissements IMMO COR | I10: =ACTIF!C7 -> 39512791
C11: 116 | D11: Retraitement dotations aux amortissements IMMO COR | J11: =ACTIF!C7 -> 39512791
B12: 48 | D12: Retraitement Provisions sur créance | I12: =+ACTIF!C22 -> 91095376
C13: 116 | D13: Retraitement Provisions sur créance | J13: =+ACTIF!C22 -> 91095376
B14: 39 | D14: Retraitement stocks | I14: =+ACTIF!C21 -> 0
C15: 116 | D15: Retraitement des stocks | J15: =+ACTIF!C21 -> 0
D16: Autres retraitements d'actif | I16: =ACTIF!C24+ACTIF!C25+ACTIF!C26 -> 0
D17: Autres retraitements d'actif | J17: =+ACTIF!C24+ACTIF!C25+ACTIF!C26 -> 0
B24: Total journal | I24: =SUM(I8:I23) -> 131174967 | J24: =SUM(J8:J23) -> 131174967
B27: Dettes par age
B29: Désignations | F29: Total | H29: Moins 1 an | J29: Plus 1 an
B30: Fournisseurs et comptes rattachés | F30: =PASSIF!B24 -> 8741154 | H30: 3541000 | J30: =+F30-H30 -> 5200154
B31: Impôts | F31: =PASSIF!B25 -> 50109882 | H31: 25000000 | J31: =+F31-H31 -> 25109882
B32: Autres dettes | F32: =PASSIF!B26 -> 36877639 | H32: 16500000 | J32: =+F32-H32 -> 20377639
F33: =SUM(F30:F32) -> 95728675 | H33: =SUM(H30:H32) -> 45041000 | J33: =SUM(J30:J32) -> 50687675

Sheet Bilan_financier
B5: ACTIF
B7: LIBELLE | C7: N | D7: %
F8: Capitaux Propres | G8: =PASSIF!B16+Journal_retraitement!J9+Journal_retraitement!J11+Journal_retraitement!J13+Journal_retraitement!J15+Journal_retraitement!J17 -> 281102632
F9: Capital émis | G9: 354480000
B10: ACTIFS NON COURANTS | F10: Capital non appelé
B11: Ecart d'acquisition-goodwill positif ou négatif | F11: Primes et réserves - Réserves consolidées | G11: 2575000
B12: Immobilisations incorporelles | C12: 67810.35 | F12: Ecart de réévaluationx
B13: Immobilisations corporelles | F13: Ecart d'équivalence
B14: Terrainsx | F14: Résultat net - Résultat net part du groupe | G14: -1.5434409e+08
B15: Bâtiments | C15: 3232650 | F15: Autres capitaux propores - Report à nouveau | G15: -4.3876675e+08
B16: Autres immobilisations corporelles | C16: 11833190 | F16: Part de la société consolidante
B17: Immobilisations en concession | F17: Part des minoritaires
B18: Immobilisations encours | C18: 10591505 | F18: TOTAL | G18: =SUM(G9:G15) -> -2.3605584e+08
B19: Immobilisations financières | F19: D.L.M.T | G19: =PASSIF!B22+Journal_retraitement!J30+Journal_retraitement!J31+Journal_retraitement!J32 -> 54773407
B20: Titres mis en équivalence | F20: Emprunts et dettes financières | G20: 9684114.8
B21: Autres participations et créances rattachées | F21: Impôts (différés et provisionnés)
B22: Autres titres immobilisés | F22: Autres dettes non courantes
B23: Prêts et autres actifs financiers non courants | C23: 21350000 | F23: Provisions et produits constatés d'avance | G23: 40486561
B24: Impôts différés actif | C24: 4745165.2 | F24: TOTAL | G24: =SUM(G20:G23) -> 50170676
B25: Actifs Fixes | C25: =+ACTIF!D19+Journal_retraitement!I8+Journal_retraitement!I10 -> 89729623 | D25: =C25/C38 -> 0.23556211 | G25: =Journal_retraitement!H30+Journal_retraitement!H31+Journal_retraitement!H32 -> 45041000
B26: ACTIF COURANT | D26: =IFERROR(C26/C38,0) -> 0 | F26: Fournisseurs et comptes rattachés | G26: 1.5960828e+08
B27: Stocks et encours | C27: 5.3558136e+08 | D27: =IFERROR(C27/C38,0) -> 1.4060315 | F27: Impôts | G27: 12042383
B28: Créances et emplois assimilés | D28: =IFERROR(C28/C38,0) -> 0 | F28: Autres dettes | G28: 6.4897046e+08
B29: Clients | C29: 9387054 | D29: =IFERROR(C29/C38,0) -> 0.024643303 | F29: Trésorerie passif
B30: Autres débiteurs | C30: 4172347.2 | D30: =IFERROR(C30/C38,0) -> 0.010953428 | F30: TOTAL | G30: =SUM(G26:G29) -> 8.2062113e+08
B31: Impôts et assimilés | C31: 28906594 | D31: =C31/C44 -> 0.10283288 | F31: TOTAL PASSIF | G31: =+G8+G19+G25 -> 380917039
B32: Autres créances et emplois assimilés | D32: =C32/C45 -> 0
B33: Disponibilités et assimilés | D33: =IFERROR(C33/C38,0) -> 0
B34: Placements et autres actifs financiers courants | D34: =C34/C47 -> 0
B35: Trésorerie | C35: 4868294.3 | D35: =IFERROR(C35/C38,0) -> 0.012780458
B36: Actifs circulants | C36: =+ACTIF!D30+Journal_retraitement!I12-ACTIF!D29 -> 232091482 | D36: =C36/C38 -> 0.60929666
B37: Disponibilités | C37: =+ACTIF!D29 -> 59095935 | D37: =C37/C38 -> 0.15514122
B38: TOTAL ACTIF | C38: =C36+C25+C37 -> 380917040 | D38: =+D25+D36+D37 -> 1
B41: PASSIF
B43: LIBELLE | C43: N
B44: Capitaux Propres | C44: =+PASSIF!B16+Journal_retraitement!J9+Journal_retraitement!J11+Journal_retraitement!J13+Journal_retraitement!J15+Journal_retraitement!J17 -> 281102632 | D44: =+C44/C67 -> 0.73796287 | E44: Capitaux permanents | F44: =+C44+C55 -> 335876039 | G44: =+F44/C67 -> 0.88175641
B45: Capital émis | C45: 354480000
B46: Capital non appelé
B47: Primes et réserves - Réserves consolidées | C47: 2575000
B48: Ecart de réévaluationx
...

Sheet TR
A3: TAFADIS
A4: Libellé | B4: réalisation 2025 | C4: réalisation 2024 | D4: Evolution % (25 / 24)
A5: Vente et produits annexes (CHIFFRE D'AFFAIRES) | B5: 638069411 | C5: 6.9249058e+08 | D5: =(B5-C5)/ABS(C5)*100 -> -7.8587598
A6: Variation stocks produits finis et en cours
A7: Production immobilisée
A8: Subventions d'exploitation
A9: I-Production de l’exercice : | B9: =SUM(B5:B8) -> 638069411 | C9: =SUM(C5:C8) -> 6.9249058e+08 | D9: =(B9-C9)/ABS(C9)*100 -> -7.8587598
A10: Achats consommés | B10: -11653629 | C10: -13489893 | D10: =(B10-C10)/ABS(C10)*100 -> 13.612146
A11: Services extérieurs et autres consommations | B11: -13343620 | C11: -23761354 | D11: =(B11-C11)/ABS(C11)*100 -> 43.843182
A12: II-Consommations de l’exercice | B12: =SUM(B10:B11) -> -24997249 | C12: =SUM(C10:C11) -> -37251247 | D12: =(B12-C12)/ABS(C12)*100 -> 32.895537
A13: III-Valeur ajoutée d’exploitation : | B13: =B9+B12 -> 613072162 | C13: =C9+C12 -> 6.5523934e+08 | D13: =(B13-C13)/ABS(C13)*100 -> -6.435385
A14: Charges de personnels | B14: -471719563 | C14: -6.4509495e+08 | D14: =(B14-C14)/ABS(C14)*100 -> 26.875949
A15: Impôts, taxes et versements assimilés | B15: -7763815 | C15: -11723164 | D15: =(B15-C15)/ABS(C15)*100 -> 33.773726
A16: IV- Excédent brut d’exploitation : | B16: =B13+B14+B15 -> 133588784 | C16: =C13+C14+C15 -> -1578779.9 | D16: =(B16-C16)/ABS(C16)*100 -> 8561.5204
A17: Autres produits opérationnels | B17: 210767 | C17: 1824099 | D17: =(B17-C17)/ABS(C17)*100 -> -88.445419
A18: Autres charges opérationnels | B18: -2689760 | C18: -1367044.9 | D18: =(B18-C18)/ABS(C18)*100 -> -96.757256
A19: Dot aux amortissements et provisions | B19: -106225700 | C19: -10170525 | D19: =(B19-C19)/ABS(C19)*100 -> -944.44654
A20: Reprise sur pertes de valeur et provisions | C20: 19404054 | D20: =(B20-C20)/ABS(C20)*100 -> -100
A21: V- Résultat opérationnel | B21: =SUM(B16:B20) -> 24884091 | C21: =SUM(C16:C20) -> 8111802.6 | D21: =(B21-C21)/ABS(C21)*100 -> 206.76401
A22: Produits financiers
A23: Charges financières
A24: VI- Résultat financier : | B24: =SUM(B22:B23) -> 0 | C24: =SUM(C22:C23) -> 0
A25: VII-Résultat ordinaire avant impôt (v + vi) : | B25: =B21+B24 -> 24884091 | C25: =C21+C24 -> 8111802.6 | D25: =(B25-C25)/ABS(C25)*100 -> 206.76401
A27: Impôts exigibles sur résultats ordinaires | B27: -8003760 | C27: -4720860 | D27: =(B27-C27)/ABS(C27)*100 -> -69.540296
A28: Impôts différé (variation) sur résultat ordinaires | B28: 5900438
A29: TOTAL DES PRODUITS DES ACTIVITES ORDINAIRES | B29: =B9+B17+B20+B22 -> 638280178 | C29: =C9+C17+C20+C22 -> 7.1371874e+08 | D29: =(B29-C29)/ABS(C29)*100 -> -10.569788
A30: TOTAL DES CHARGES DES ACTIVITES ORDINAIRES | B30: =B12+B14+B15+B18+B19+B23+B27+B28 -> -615499409 | C30: =C12+C14+C15+C18+C19+C23+C27+C28 -> -7.1032779e+08 | D30: =(B30-C30)/ABS(C30)*100 -> 13.349947
A31: VIII.RESULTAT NET DES ACTIVITES ORDINAIRES | B31: =B29+B30 -> 22780769 | C31: =C29+C30 -> 3390942.6 | D31: =(B31-C31)/ABS(C31)*100 -> 571.81229
A32: Eléments extraordinaire (produits) (à préciser)
A33: Eléments extraordinaire (charges) (à préciser)
A34: Résultat Net de l'exercice | B34: =B31+B32-B33 -> 22780769 | C34: =C31+C32-C33 -> 3390942.6 | D34: =(B34-C34)/ABS(C34)*100 -> 571.81229
A35: CAF | B35: =+B34-B19-B20 -> 129006469 | C35: =+C34-C19-C20 -> -5842585.8
B39: Actif net | C39: Investissement
A40: Exercice 2025 | B40: =PASSIF!B16/1000000 -> 149.92766 | C40: =(ACTIF!B6+ACTIF!B7+ACTIF!B12)/1000000 -> 82.502586
A41: Exercice 2024 | B41: =PASSIF!B16/1000000 -> 149.92766 | C41: =1411218208.18/1000000 -> 1411.2182
